<?xml version="1.0" ?>

<!-- Robot Description format of custom 6DOF Yeti CLARM (Yeti Clamsy Arm) arm
	 Anna Safonov - anna.safonov@uoit.net
	 28/06/2016

Notes:

For collision tags of the first six links, same meshes were used as in visual tag. No simpler meshes are available yet for this arm. Since there are no sensitive parts on the arm and the arm is not too complicated, the actual mesh was deemed appropriate for the purpose of collision calculations.

The gripper links and joints were modified from the urdf of rst-tu-dortmund/phantomx_rst repo, and all the meshes were taken from that library, since both arms share the same gripper. 

Inertia tags were done using MeshLab;Scale set to 0.01 of original for each stl, and inertia tensors calulated with Filters -> Quality Measure and Computations -> Compute Geometric Measures. Instructions: https://www.youtube.com/watch?v=V97mRECS5oI


Documentation:

URDF
http://www.ros.org/wiki/urdf/XML


Joint Safety Limits
http://www.ros.org/wiki/pr2_controller_manager/safety_limits


XARCO - Macro Language
http://www.ros.org/wiki/xacro


Gazebo Modeling
http://www.ros.org/wiki/simulator_gazebo/Tutorials/SpawningObjectInSimulation
http://gazebosim.org/tutorials?tut=inertia&amp%3Bcat=
-->


<robot name = "clarm">

 <!-- Material specification -->
	<material name = "Grey">
	    <color rgba = "0.4 0.4 0.4 1.0"/>
	</material>

	<material name="Black">
    	    <color rgba="0.0 0.0 0.0 1.0"/>
  	</material>

  	<material name="Blue">
            <color rgba="0.0 0.0 0.8 1.0"/>
  	</material>

  	<material name="Green">
            <color rgba="0.0 0.8 0.0 1.0"/>
	</material>

	<material name="Orange">
            <color rgba="0.65 0.42 0.07 1.0"/>
	</material>

	<material name="Red">
            <color rgba="0.8 0.0 0.0 1.0"/>
 	</material>

	<material name="White">
            <color rgba="1.0 1.0 1.0 1.0"/>
	</material>

 <!-- To fix the arm in the Gazebo world. Comment out for MoveIt. -->
 <!--<link name="world"/>

	<joint name="fixed" type="fixed">
		<parent link="world"/>
		<child link="base_link"/>
	</joint> -->

 <!-- BASE LINK -->
	<link name = "base_link">
	<!--	<inertial>
      		<origin xyz="0 0 0"/>
      		<mass value="1.0"/>
      		<inertia ixx="1.0" ixy="0.0" ixz="0.0" 
      				 iyy="100.0" iyz="0.0" 
      				 izz="1.0"/>
		</inertial>
	--> <!-- Uncomment the above inertial tag for Gazebo, comment out for Moveit -->
        <visual>
			<origin rpy = "0 0 0" xyz = "0 0 0"/>
                <geometry>
                   <mesh filename="package://clarm_description/meshes/base_link.stl" scale = "0.001 0.001 0.001"/>  
                </geometry>
			<material name = "Grey"/>
        </visual>
        <collision>
      		<origin rpy="0 0 0" xyz="0 0 0"/>
      		<geometry>
        			<mesh filename="package://clarm_description/meshes/base_link.stl" scale = "0.001 0.001 0.001"/>
      		</geometry>
    	</collision>
	</link>

	<gazebo reference="base_link">
    	<material>Gazebo/Grey</material>
    	<selfCollide>true</selfCollide>
    	<gravity>true</gravity>
  	</gazebo>

 <!-- SHOULDER PAN JOINT -->
	<joint name = "shoulder_pan_joint" type = "revolute">
		<parent link="base_link" />
		<child link="shoulder_pan_link"/>
		<origin rpy="0 -1.57 0" xyz="0 0.055 0.06"/>
		<axis xyz="1 0 0" />
		<limit effort="300" lower="-2.61799387799" upper="1.98394848567" velocity="1"/>
		<dynamics damping="50" friction="1"/>
  	</joint>

 <!-- SHOULDER PAN LINK -->
	<link name = "shoulder_pan_link">
		<inertial>
      		<origin xyz="0 0 0"/>
      		<mass value="1.0"/>
      		<inertia ixx="1.0" ixy="0.0" ixz="0.0" 
      				 iyy="100.0" iyz="0.0" 
      				 izz="1.0"/>
		</inertial>
	    <visual>
			<origin rpy="0 0 0" xyz="0 0 0"/>
                <geometry>
		   			<mesh filename="package://clarm_description/meshes/shoulder_pan_link.stl" scale = "0.001 0.001 0.001"/>
                </geometry>
			<material name = "Orange"/>
        </visual>
        <collision>
      		<origin rpy="0 0 0" xyz="0 0 0"/>
      		<geometry>
        			<mesh filename="package://clarm_description/meshes/shoulder_pan_link.stl" scale = "0.001 0.001 0.001"/>
      		</geometry>
    	</collision>
    </link>

    <gazebo reference="shoulder_pan_link">
    	<material>Gazebo/Orange</material>
    	<selfCollide>true</selfCollide>
    	<gravity>true</gravity>
  	</gazebo>

 <!-- SHOULDER PITCH JOINT -->
	<joint name="shoulder_pitch_joint" type="revolute">
		<parent link="shoulder_pan_link" />	
		<child link="shoulder_pitch_link"/>
		<origin rpy="0 0 0" xyz="0.0235 -0.0065 0.031"/> 
		<axis xyz="0 0 1" />
		<limit effort="300" lower="-1.19962513147" upper="1.55" velocity="1"/>
		<dynamics damping="50" friction="1"/>
  	</joint>

 <!-- SHOULDER PITCH LINK -->
	<link name = "shoulder_pitch_link">
		<inertial>
      		<origin xyz="0 0 0"/>
      		<mass value="1.0"/>
      		<inertia ixx="1.0" ixy="0.0" ixz="0.0" 
      				 iyy="100.0" iyz="0.0" 
      				 izz="1.0"/>
		</inertial>
	    <visual>
			<origin rpy="0 0 0" xyz="0 0 0"/>
                <geometry>
                    <mesh filename="package://clarm_description/meshes/shoulder_pitch_link.stl" scale = "0.001 0.001 0.001"/>
                </geometry>
			<material name = "Grey"/>
        </visual>
        <collision>
      		<origin rpy="0 0 0" xyz="0 0 0"/>
      		<geometry>
        			<mesh filename="package://clarm_description/meshes/shoulder_pitch_link.stl" scale = "0.001 0.001 0.001"/>
      		</geometry>
    	</collision>
    </link>

    <gazebo reference="shoulder_pitch_link">
    	<material>Gazebo/Grey</material>
    	<selfCollide>true</selfCollide>
    	<gravity>true</gravity>
  	</gazebo>

 <!-- ELBOW PITCH JOINT -->
	<joint name="elbow_pitch_joint" type="revolute">
		<parent link="shoulder_pitch_link"/>
		<child link="elbow_pitch_link"/>
		<origin rpy = "0 1.57 0" xyz = "0.136 0.0335 -0.002"/>
		<axis xyz="1 0 0" />
		<limit effort="300" lower="-1.5953400194" upper="0" velocity="1"/>
		<dynamics damping="50" friction="1"/>
  	</joint>

 <!-- ELBOW PITCH LINK -->
	<link name = "elbow_pitch_link">
		<inertial>
      		<origin xyz="0 0 0"/>
      		<mass value="1.0"/>
      		<inertia ixx="1.0" ixy="0.0" ixz="0.0" 
      				 iyy="100.0" iyz="0.0" 
      				 izz="1.0"/>
		</inertial>
	    <visual>
			<origin rpy = "0 0 0" xyz = "0 0 0"/>
                <geometry>
                    <mesh filename="package://clarm_description/meshes/elbow_pitch_link.stl" scale = "0.001 0.001 0.001"/>
                </geometry>
			<material name = "Orange"/>
        </visual>
        <collision>
      		<origin rpy="0 0 0" xyz="0 0 0"/>
      		<geometry>
        			<mesh filename="package://clarm_description/meshes/elbow_pitch_link.stl" scale = "0.001 0.001 0.001"/>
      		</geometry>
    	</collision>
    </link>

    <gazebo reference="elbow_pitch_link">
    	<material>Gazebo/Orange</material>
    	<selfCollide>true</selfCollide>
    	<gravity>true</gravity>
  	</gazebo>

 <!-- ELBOW ROLL JOINT -->
	<joint name="elbow_roll_joint" type="revolute">
		<parent link="elbow_pitch_link"/>
		<child link="elbow_roll_link"/>
		<origin rpy = "1.57 0 -1.57" xyz = "0.025 0.015 0.065"/>
		<axis xyz="0 1 0" />
		<limit effort="300" lower="-2.61799387799" upper="0.705631162427" velocity="1"/>
		<dynamics damping="50" friction="1"/>
  	</joint>

 <!-- ELBOW ROLL LINK -->
	<link name = "elbow_roll_link">
		<inertial>
      		<origin xyz="0 0 0"/>
      		<mass value="1.0"/>
      		<inertia ixx="1.0" ixy="0.0" ixz="0.0" 
      			 	 iyy="100.0" iyz="0.0" 
      			 	 izz="1.0"/>
		</inertial>
        <visual>
			<origin rpy = "0 0 0" xyz = "0 0 0"/>
                <geometry>
                    <mesh filename="package://clarm_description/meshes/elbow_roll_link.stl" scale = "0.001 0.001 0.001"/>
                </geometry>
			<material name = "Grey"/>
        </visual>
        <collision>
      		<origin rpy="0 0 0" xyz="0 0 0"/>
      		<geometry>
        			<mesh filename="package://clarm_description/meshes/elbow_roll_link.stl" scale = "0.001 0.001 0.001"/>
      		</geometry>
    	</collision>
    </link>

    <gazebo reference="elbow_roll_link">
    	<material>Gazebo/Grey</material>
    	<selfCollide>true</selfCollide>
    	<gravity>true</gravity>
  	</gazebo>

 <!-- WRIST PITCH JOINT -->
	<joint name="wrist_pitch_joint" type="revolute">
		<parent link="elbow_roll_link"/>
		<child link="wrist_pitch_link"/>
		<origin rpy = "0 1.57 1.57" xyz = "0 0.042 -0.025"/>
		<axis xyz="1 0 0" />
		<limit effort="300" lower="-1.5953400194" upper="1.98394848567" velocity="1"/>
		<dynamics damping="50" friction="1"/>
 	 </joint>

 <!-- WRIST PITCH LINK -->
	<link name = "wrist_pitch_link">
		<inertial>
      		<origin xyz="0 0 0"/>
      		<mass value="1.0"/>
     		<inertia ixx="1.0" ixy="0.0" ixz="0.0" 
     				 iyy="100.0" iyz="0.0" 
     				 izz="1.0"/>
		</inertial>
        <visual>
			<origin rpy = "0 0 0" xyz = "0 0 0"/>
                <geometry>
                    <mesh filename="package://clarm_description/meshes/wrist_pitch_link.stl" scale = "0.001 0.001 0.001"/>
                </geometry>
			<material name = "Orange"/>
        </visual>
        <collision>
      		<origin rpy="0 0 0" xyz="0 0 0"/>
      		<geometry>
        			<mesh filename="package://clarm_description/meshes/wrist_pitch_link.stl" scale = "0.001 0.001 0.001"/>
      		</geometry>
    	</collision>
    </link>

    <gazebo reference="wrist_pitch_link">
    	<material>Gazebo/Orange</material>
    	<selfCollide>true</selfCollide>
    	<gravity>true</gravity>
  	</gazebo>

 <!-- WRIST ROLL JOINT -->
	<joint name="wrist_roll_joint" type="revolute">
		<parent link="wrist_pitch_link"/>
		<child link="wrist_roll_link" />
		<origin rpy = "0 0 3.14" xyz = "-0.0245 0.02 0.065"/>
		<axis xyz="0 0 1" />
		<limit effort="300" lower="-2.61799387799" upper="2.6128806087" velocity="1"/>
		<dynamics damping="50" friction="1"/>
  	</joint>

 <!-- WRIST ROLL LINK -->
	<link name = "wrist_roll_link">
		<inertial>
      		<origin xyz="0 0 0"/>
      		<mass value="1.0"/>
      		<inertia ixx="1.0" ixy="0.0" ixz="0.0" 
      				 iyy="100.0" iyz="0.0" 
      				 izz="1.0"/>
		</inertial>
        <visual>
			<origin rpy = "0 0 0" xyz = "0 0 0"/>
                <geometry>
                    <mesh filename="package://clarm_description/meshes/wrist-roll.stl" scale = "0.001 0.001 0.001"/>
                </geometry>
			<material name = "Grey"/>
        </visual>
        <collision>
      		<origin rpy="0 0 0" xyz="0 0 0"/>
      		<geometry>
        			<mesh filename="package://clarm_description/meshes/wrist-roll.stl" scale = "0.001 0.001 0.001"/>
      		</geometry>
    	</collision>
    </link>

    <gazebo reference="wrist_roll_link">
    	<material>Gazebo/Grey</material>
    	<selfCollide>true</selfCollide>
    	<gravity>true</gravity>
  	</gazebo>

 <!-- GRIPPER BASE JOINT -->
 	<joint name="gripper_base_joint" type="fixed">
    	<parent link="wrist_roll_link"/>
    	<child link="gripper_finger_base_link"/>
    	<origin rpy="1.570795 -1.570795 1.570795" xyz="0.015  0.02 0.022"/>
  	</joint>

 <!-- GRIPPER FINGER BASE LINK -->
  	<link name="gripper_finger_base_link">
    	<inertial>
     		<mass value="0.00001"/>
      		<origin xyz="0 0 0"/>
      		<inertia ixx="1.0" ixy="0.0" ixz="0.0" 
      				 iyy="1.0" iyz="0.0" 
      				 izz="1.0"/>
    	</inertial>
    	<visual>
      		<origin rpy="3.14159 -1.570795 1.570795" xyz="0.016 0 -.015 "/>
      		<geometry>
       			<mesh filename="package://clarm_description/meshes/pincher_finger_base.stl" scale=".01 .01 .01"/>
      		</geometry>
      		<material name="Orange"/>
    	</visual>
    	<collision>
      		<origin rpy="0 0 0" xyz="0.015 0 -0.0135"/>
      		<geometry>
        		<box size="0.002 0.040 0.075"/>
      		</geometry>
    	</collision>
  	</link>

 	<gazebo reference="gripper_finger_base_link">
    	<material>Gazebo/Orange</material>
    	<selfCollide>true</selfCollide>
    	<gravity>true</gravity>
  	</gazebo>

 <!-- GRIPPER JOINT -->
  	<joint name="gripper_joint" type="prismatic">
   		<origin rpy="1.57 0 0" xyz="0.01 0.02 0.019"/>
    	<axis xyz="1 0 0"/>
    	<limit effort="30" lower="0.002" upper="0.031" velocity="0.5"/>
    	<parent link="wrist_roll_link"/>
    	<child link="gripper_active_link"/>
  	</joint>

 <!-- GRIPPER ACTIVE LINK -->
  	<link name="gripper_active_link">
    	<inertial>
      		<mass value="0.00001"/>
      		<origin xyz="0 0 0"/>
      		<inertia ixx="1.0" ixy="0.0" ixz="0.0" 
      				 iyy="1.0" iyz="0.0" 
      				 izz="1.0"/>
    	</inertial>
    	<visual>
     		<origin rpy="-1.57 0 0" xyz="-0.02 0.023 0"/>
      		<geometry>
        			<mesh filename="package://clarm_description/meshes/pincher_finger.stl" scale=".01 .01 .01"/>
      		</geometry>
      		<material name="Orange"/>
    	</visual>
    	<collision>
      		<origin rpy="-1.570795 0 0" xyz="-0.02 0.023 0"/>
      		<geometry>
        			<box size="0.036 0.028 0.004"/>
      		</geometry>
    	</collision>
	</link>

	<gazebo reference="gripper_active_link">
    	<material>Gazebo/Orange</material>
    	<selfCollide>true</selfCollide>
    	<gravity>true</gravity>
  	</gazebo>

 <!-- GRIPPER2 JOINT -->
  	<joint name="gripper2_joint" type="fixed">
  		<origin rpy="1.57 0 0" xyz="0.01 0.02 0.019"/>
    	<parent link="wrist_roll_link"/>
    	<child link="gripper_active2_link"/>
  	</joint>

 <!-- GRIPPER ACTIVE2 LINK -->
  	<link name="gripper_active2_link">
    	<inertial>
      		<mass value="0.00001"/>
      		<origin xyz="0 0 0"/>
      	<inertia ixx="1.0" ixy="0.0" ixz="0.0" 
      			 iyy="1.0" iyz="0.0" 
      			 izz="1.0"/>
    	</inertial>
    	<visual>
     		<origin rpy="-1.57 3.14159 0" xyz="-0.02 0.023 0"/>
      		<geometry>
        			<mesh filename="package://clarm_description/meshes/pincher_finger.stl" scale=".01 .01 .01"/>
      		</geometry>
      		<material name="Orange"/>
    	</visual>
    	<collision>
      		<origin rpy="-1.570795 3.14159 0" xyz="-0.02 0.023 0"/>
      		<geometry>
        			<box size="0.036 0.028 0.004"/>
      		</geometry>
    	</collision>
  	</link>

  	<gazebo reference="gripper_active2_link">
    	<material>Gazebo/Orange</material>
    	<selfCollide>true</selfCollide>
    	<gravity>true</gravity>
	</gazebo>

</robot>

